Workbook

Sheet KPI Dashboard
A1: YoungXCode — KPI Dashboard
A2: Auto-calculated from Clients, Projects, Tasks, Invoices sheets. Update target values (yellow) as needed.
A4: KPI | B4: Formula / Calculation Method | C4: Current Value | D4: Target | E4: Status | F4: Category
A5: Monthly Recurring Revenue (MRR) | B5: Total Invoiced Amount (incl. GST) / Number of Active Months | C5: =Calc!B3/Calc!B4 -> 877578.46 | D5: 1000000 | E5: =IF(C5>=D5,"On Track","Below Target") -> Below Target | F5: Revenue
A6: Average Project Value | B6: AVERAGE(Project Budget) across all projects | C6: =AVERAGE(Projects!G2:G81) -> 1169068.9 | D6: 1200000 | E6: =IF(C6>=D6,"On Track","Below Target") -> Below Target | F6: Revenue
A7: Invoice Collection Rate | B7: SUM(Paid Invoices Total) / SUM(Total Invoiced) x 100 | C7: =Calc!B5/Calc!B3 -> 0.51696592 | D7: 0.85 | E7: =IF(C7>=D7,"On Track","Below Target") -> Below Target | F7: Revenue
A8: Overdue Amount | B8: SUM(Total Amount) where Payment Status is Overdue/Unpaid/Partially Paid AND Due Date < Today | C8: =Calc!B6 -> 14412610 | D8: 500000 | E8: =IF(C8<=D8,"On Track","Above Target") -> Above Target | F8: Revenue
A9: On-Time Delivery Rate | B9: COUNT(Completed Projects, Actual End <= Deadline) / COUNT(Completed Projects) x 100 | C9: =Calc!B8/Calc!B7 -> 0.29166667 | D9: 0.9 | E9: =IF(C9>=D9,"On Track","Below Target") -> Below Target | F9: Project
A10: Average Project Duration (days) | B10: AVERAGE(Actual End Date - Start Date) for Completed Projects | C10: =Calc!B9/Calc!B10 -> 141.48936 | D10: 120 | E10: =IF(C10<=D10,"On Track","Above Target") -> Above Target | F10: Project
A11: Budget Overrun Rate | B11: COUNT(Projects where Amount Spent > Budget) / COUNT(Total Projects) x 100 | C11: =Calc!B12/Calc!B11 -> 0.2875 | D11: 0.15 | E11: =IF(C11<=D11,"On Track","Above Target") -> Above Target | F11: Project
A12: Task Completion Rate | B12: COUNT(Tasks where Status = Completed) / COUNT(Total Tasks) x 100 | C12: =Calc!B14/Calc!B13 -> 0.78666667 | D12: 0.85 | E12: =IF(C12>=D12,"On Track","Below Target") -> Below Target | F12: Team
A13: Average Hours per Task | B13: AVERAGE(Actual Hours) across all tasks | C13: =Calc!B15/Calc!B13 -> 38.671667 | D13: 35 | E13: =IF(C13<=D13,"On Track","Above Target") -> Above Target | F13: Team
A14: Team Utilization % | B14: SUM(Actual Hours) / SUM(Estimated Hours) x 100 | C14: =Calc!B15/Calc!B16 -> 0.97959166 | D14: 0.9 | E14: =IF(C14>=D14,"On Track","Below Target") -> On Track | F14: Team
A15: Client Retention Rate | B15: COUNT(Clients with Total Projects >= 1) / COUNT(Total Clients) x 100 | C15: =Calc!B18/Calc!B17 -> 0.84 | D15: 0.8 | E15: =IF(C15>=D15,"On Track","Below Target") -> On Track | F15: Client
A16: Average Projects per Client | B16: AVERAGE(Total Projects per Client) | C16: =AVERAGE(Clients!F2:F51) -> 1.6 | D16: 2 | E16: =IF(C16>=D16,"On Track","Below Target") -> Below Target | F16: Client

Sheet Calc
A1: Helper Calculations
A2: Label | B2: Value
A3: Total Invoiced (incl GST) | B3: =SUM(Invoices!I2:I61) -> 29837668
A4: Active Months Span | B4: =DATEDIF(MIN(Invoices!C2:C61),MAX(Invoices!C2:C61),"m")+1 -> 34
A5: Total Paid Amount | B5: =SUMIF(Invoices!F2:F61,"Paid",Invoices!I2:I61) -> 15425057
A6: Total Overdue Amount | B6: =SUMIF(Invoices!J2:J61,TRUE(),Invoices!I2:I61) -> 14412610
A7: Completed Projects Count | B7: =COUNTIF(Projects!I2:I81,"Completed") -> 48
A8: On-Time Completed Count | B8: =SUMPRODUCT((Projects!I2:I81="Completed")*(Projects!F2:F81<>"")*(Projects!F2:F81<=Projects!E2:E81)) -> 14
A9: Sum Duration (Completed, days) | B9: =SUMPRODUCT((Projects!I2:I81="Completed")*(Projects!F2:F81<>"")*(Projects!F2:F81-Projects!D2:D81)) -> 6650
A10: Completed Projects with Valid End Date | B10: =SUMPRODUCT((Projects!I2:I81="Completed")*(Projects!F2:F81<>"")*1) -> 47
A11: Total Projects Count | B11: =COUNTA(Projects!A2:A81) -> 80
A12: Overrun Projects Count | B12: =SUMPRODUCT((Projects!H2:H81>Projects!G2:G81)*1) -> 23
A13: Total Tasks Count | B13: =COUNTA(Tasks!A2:A301) -> 300
A14: Completed Tasks Count | B14: =COUNTIF(Tasks!I2:I301,"Completed") -> 236
A15: Sum Actual Hours | B15: =SUM(Tasks!H2:H301) -> 11601.5
A16: Sum Estimated Hours | B16: =SUM(Tasks!G2:G301) -> 11843.2
A17: Total Clients Count | B17: =COUNTA(Clients!A2:A51) -> 50
A18: Clients with Projects >=1 | B18: =COUNTIF(Clients!F2:F51,">=1") -> 42

Sheet Clients
A1: client_id | B1: client_name | C1: city | D1: industry | E1: join_date | F1: total_projects | G1: total_revenue
A2: CL1000 | B2: Apex Systems | C2: Lucknow | D2: Logistics | E2: 44730 | F2: 1 | G2: 1150740.9
A3: CL1001 | B3: Nova Corp | C3: Bangalore | D3: E-Commerce | E3: 44060 | F3: 2 | G3: 854257.39
A4: CL1002 | B4: Pixel Works | C4: Chennai | D4: Real Estate | E4: 45123 | F4: 4 | G4: 489884.4
A5: CL1003 | B5: Quantum Labs | C5: Mumbai | D5: Media | E5: 44102 | F5: 0 | G5: 1492621.2
A6: CL1004 | B6: Grand Systems | C6: Bangalore | D6: Retail | E6: 45119 | F6: 2 | G6: 3173088.7
A7: CL1005 | B7: Apex Corp | C7: Lucknow | D7: Retail | E7: 45451 | F7: 3 | G7: 209383.83
A8: CL1006 | B8: Cloud Technologies | C8: Pune | D8: Education | E8: 44416 | F8: 1 | G8: 0
A9: CL1007 | B9: Tech Hub | C9: Indore | D9: Fintech | E9: 44841 | F9: 2 | G9: 0
A10: CL1008 | B10: Swift Solutions | C10: Indore | D10: Media | E10: 44907 | F10: 2 | G10: 80360.31
A11: CL1009 | B11: Nova Systems | C11: Surat | D11: Hospitality | E11: 45585 | F11: 2 | G11: 0
A12: CL1010 | B12: Quantum Works | C12: Bangalore | D12: Education | E12: 45313 | F12: 1 | G12: 763382.97
A13: CL1011 | B13: Crest Hub | C13: Ahmedabad | D13: Healthcare | E13: 45918 | F13: 0 | G13: 2248114.2
... A51: CL1049 | B51: Grand Technologies | C51: Jaipur | D51: Hospitality | E51: 44234 | F51: 2 | G51: 685056.77

Sheet Projects
A1: project_id | B1: project_name | C1: client_name | D1: start_date | E1: deadline | F1: actual_end_date | G1: budget | H1: amount_spent | I1: status | J1: budget_utilization_pct | K1: is_overdue
A2: PRJ2000 | B2: Analytics Dashboard - Grand | C2: Grand Works | D2: 45256 | E2: 45490 | G2: 659208.02 | H2: 37616.17 | I2: Cancelled | J2: 5.71 | K2: =FALSE() -> FALSE
A3: PRJ2001 | B3: POS System - Swift | C3: Swift Solutions | D3: 45426 | E3: 45502 | F3: 45502 | G3: 2192490.6 | H3: 1609119.7 | I3: Completed | J3: 73.39 | K3: =FALSE() -> FALSE
A4: PRJ2002 | B4: Mobile App - Tech | C4: Tech Works | D4: 44762 | E4: 44804 | G4: 1374440.4 | H4: 151642.7 | I4: In Progress | J4: 11.03 | K4: =TRUE() -> TRUE
A5: PRJ2003 | B5: Website Redesign - Cloud | C5: Cloud Net | D5: 45046 | E5: 45118 | F5: 45133 | G5: 573680.88 | H5: 505107.73 | I5: Completed | J5: 88.05 | K5: =FALSE() -> FALSE
A6: PRJ2004 | B6: E-commerce Platform - Quantum | C6: Quantum Works | D6: 45338 | E6: 45368 | F6: 45394 | G6: 2319969.3 | H6: 2443642.7 | I6: Delayed | J6: 105.33 | K6: =TRUE() -> TRUE
A7: PRJ2005 | B7: Website Redesign - Crest | C7: Crest Systems | D7: 45700 | E7: 45899 | G7: 429252.22 | H7: 132078.97 | I7: Completed | J7: 30.77 | K7: =FALSE() -> FALSE
A8: PRJ2006 | B8: Payment Gateway - Swift | C8: Swift Industries | D8: 45672 | E8: 45717 | G8: 190054.92 | H8: 96723.57 | I8: On Hold | J8: 50.89 | K8: =TRUE() -> TRUE
A9: PRJ2007 | B9: Mobile App - Nova | C9: Nova Net | D9: 44884 | E9: 44928 | F9: 44943 | G9: 2135789.2 | H9: 1560908.7 | I9: Delayed | J9: 73.08 | K9: =TRUE() -> TRUE
A10: PRJ2008 | B10: Cloud Migration - Grand | C10: Grand Net | D10: 45043 | E10: 45176 | F10: 45197 | G10: 653227.6 | H10: 632019.66 | I10: Completed | J10: 96.75 | K10: =FALSE() -> FALSE
A11: PRJ2009 | B11: CRM Integration - Apex | C11: Apex Corp | D11: 45420 | E11: 45618 | G11: 1330817.6 | H11: 1003828.3 | I11: In Progress | J11: 75.43 | K11: =TRUE() -> TRUE
A12: PRJ2010 | B12: Inventory Management - Apex | C12: Apex Industries | D12: 45205 | E12: 45296 | F12: 45289 | G12: 1118340.9 | H12: 1415858.1 | I12: Completed | J12: 126.6 | K12: =FALSE() -> FALSE
A13: PRJ2011 | B13: CRM Integration - Cloud | C13: Cloud Net | D13: 44710 | E13: 44742 | F13: 44763 | G13: 2490436.3 | H13: 1825408.4 | I13: Completed | J13: 73.3 | K13: =FALSE() -> FALSE
A14: PRJ2012 | B14: ERP System - Vivid | C14: Vivid Works | D14: 45105 | E14: 45168 | F14: 45182 | G14: 2204212.1 | H14: 1909480.7 | I14: Delayed | J14: 86.63 | K14: =TRUE() -> TRUE
A15: PRJ2013 | B15: Payment Gateway - Cloud | C15: Cloud Group | D15: 45674 | E15: 45884 | F15: 45910 | G15: 1345904.7 | H15: 1346629.4 | I15: Completed | J15: 100.05 | K15: =FALSE() -> FALSE
A16: PRJ2014 | B16: Marketing Website - Grand | C16: Grand Group | D16: 45920 | E16: 45976 | F16: 45994 | G16: 697941.51 | H16: 767994.4 | I16: Delayed | J16: 110.04 | K16: =TRUE() -> TRUE
A17: PRJ2015 | B17: API Development - Tech | C17: Tech Works | D17: 44880 | E17: 44979 | F17: 44977 | G17: 1808149.9 | H17: 0 | I17: Completed | J17: 0 | K17: =FALSE() -> FALSE
A18: PRJ2016 | B18: E-commerce Platform - Vivid | C18: Vivid Industries | D18: 45597 | E18: 45752 | F18: 45740 | G18: 276131.25 | H18: 245925 | I18: Completed | J18: 89.06 | K18: =FALSE() -> FALSE
A19: PRJ2017 | B19: Marketing Website - Pixel | C19: Pixel Works | D19: 44569 | E19: 44684 | G19: 1610927.8 | H19: 456486.48 | I19: On Hold | J19: 28.34 | K19: =TRUE() -> TRUE
A20: PRJ2018 | B20: Marketing Website - Cloud | C20: Cloud Group | D20: 45691 | E20: 45901 | F20: 45886 | G20: 324091.01 | H20: 364690.84 | I20: Completed | J20: 112.53 | K20: =FALSE() -> FALSE
A21: PRJ2019 | B21: ERP System - Nova | C21: Nova Systems | D21: 45679 | E21: 45718 | G21: 1477148.4 | H21: 65626.95 | I21: Cancelled | J21: 4.44 | K21: =FALSE() -> FALSE
A22: PRJ2020 | B22: Inventory Management - Pixel | C22: Pixel Works | D22: 45193 | E22: 45316 | F22: 45376 | G22: 2431880.9 | H22: 1745975.4 | I22: Delayed | J22: 71.8 | K22: =TRUE() -> TRUE
A23: PRJ2021 | B23: Cloud Migration - Quantum | C23: Quantum Corp | D23: 45073 | E23: 45273 | F23: 45293 | G23: 2216130 | H23: 1956554.3 | I23: Completed | J23: 88.29 | K23: =FALSE() -> FALSE
A24: PRJ2022 | B24: HRMS Portal - Bright | C24: Bright Enterprises | D24: 44941 | E24: 44968 | G24: 2441704.8 | H24: 593899.56 | I24: Cancelled | J24: 24.32 | K24: =FALSE() -> FALSE
A25: PRJ2023 | B25: POS System - Grand | C25: Grand Enterprises | D25: 44612 | E25: 44687 | G25: 863854.4 | H25: 649248.02 | I25: On Hold | J25: 75.16 | K25: =TRUE() -> TRUE
A26: PRJ2024 | B26: LMS Platform - Apex | C26: Apex Industries | D26: 45070 | E26: 45168 | F26: 45197 | G26: 314834.28 | H26: 343948.6 | I26: Completed | J26: 109.25 | K26: =FALSE() -> FALSE
A27: PRJ2025 | B27: POS System - Pixel | C27: Pixel Net | D27: 45017 | E27: 45098 | G27: 1177742.9 | H27: 107830.91 | I27: Cancelled | J27: 9.16 | K27: =FALSE() -> FALSE
A28: PRJ2026 | B28: Mobile App - Crest | C28: Crest Group | D28: 45018 | E28: 45054 | G28: 1026241.7 | H28: 302764.01 | I28: In Progress | J28: 29.5 | K28: =TRUE() -> TRUE
A29: PRJ2027 | B29: Payment Gateway - Grand | C29: Grand Technologies | D29: 45133 | E29: 45252 | G29: 1029212 | H29: 809788.95 | I29: In Progress | J29: 78.68 | K29: =TRUE() -> TRUE
A30: PRJ2028 | B30: E-commerce Platform - Bright | C30: Bright Works | D30: 44618 | E30: 44677 | G30: 689977.23 | H30: 120178.11 | I30: Cancelled | J30: 17.42 | K30: =FALSE() -> FALSE
A31: PRJ2029 | B31: Mobile App - Pixel | C31: Pixel Works | D31: 44784 | E31: 44966 | F31: 44971 | G31: 1119165 | H31: 1279100.6 | I31: Completed | J31: 114.29 | K31: =FALSE() -> FALSE
A32: PRJ2030 | B32: POS System - Swift | C32: Swift Systems | D32: 45742 | E32: 45820 | F32: 45850 | G32: 1118340.9 | H32: 1044490.3 | I32: Completed | J32: 93.4 | K32: =FALSE() -> FALSE
A33: PRJ2031 | B33: API Development - Quantum | C33: Quantum Industries | D33: 44965 | E33: 45088 | F33: 45115 | G33: 2305888.6 | H33: 2260739.1 | I33: Completed | J33: 98.04 | K33: =FALSE() -> FALSE
A34: PRJ2032 | B34: Payment Gateway - Tech | C34: Tech Hub | D34: 45177 | E34: 45336 | F34: 45347 | G34: 849148.12 | H34: 860818.63 | I34: Completed | J34: 101.37 | K34: =FALSE() -> FALSE
A35: PRJ2033 | B35: ERP System - Swift | C35: Swift Solutions | D35: 44954 | E35: 45091 | G35: 978905.93 | H35: 610537.94 | I35: In Progress | J35: 62.37 | K35: =TRUE() -> TRUE
A36: PRJ2034 | B36: POS System - Silver | C36: Silver Ventures | D36: 45727 | E36: 45834 | F36: 45819 | G36: 794493.63 | H36: 631290.5 | I36: Completed | J36: 79.46 | K36: =FALSE() -> FALSE
A37: PRJ2035 | B37: Analytics Dashboard - Swift | C37: Swift Industries | D37: 45804 | E37: 46001 | F37: 46014 | G37: 1133291.5 | H37: 902287.75 | I37: Completed | J37: 79.62 | K37: =FALSE() -> FALSE
A38: PRJ2036 | B38: Mobile App - Bright | C38: Bright Enterprises | D38: 44909 | E38: 45107 | F38: 45124 | G38: 1676441.9 | H38: 1640679 | I38: Completed | J38: 97.87 | K38: =FALSE() -> FALSE
A39: PRJ2037 | B39: Analytics Dashboard - Cloud | C39: Cloud Net | D39: 45043 | E39: 45245 | F39: 45242 | G39: 411017.21 | H39: 296259.63 | I39: Completed | J39: 72.08 | K39: =FALSE() -> FALSE
A40: PRJ2038 | B40: Booking System - Silver | C40: Silver Ventures | D40: 44711 | E40: 44857 | F40: 44882 | G40: 1460393.7 | H40: 1494356.1 | I40: Completed | J40: 102.33 | K40: =FALSE() -> FALSE
...

Sheet Tasks
A1: task_id | B1: project_name | C1: assignee | D1: priority | E1: created_date | F1: completed_date | G1: estimated_hours | H1: actual_hours | I1: task_status | J1: hours_variance
A2: TSK3000 | B2: POS System - Vivid | C2: Tanvi Desai | D2: Medium | E2: 45525 | F2: 45565 | G2: 76.9 | H2: 53.8 | I2: Completed | J2: -23.1
A3: TSK3001 | B3: Payment Gateway - Grand | C3: Priya Singh | D3: Low | E3: 45200 | F3: 45211 | G3: 20.7 | H3: 23.8 | I3: Completed | J3: 3.1
A4: TSK3002 | B4: Website Redesign - Silver | C4: Siddharth Iyer | D4: High | E4: 46034 | F4: 46065 | G4: 24.7 | H4: 20.5 | I4: Completed | J4: -4.2
A5: TSK3003 | B5: HRMS Portal - Grand | C5: Pooja Reddy | D5: Medium | E5: 44915 | F5: 44932 | G5: 63.5 | H5: 77.8 | I5: Completed | J5: 14.3
A6: TSK3004 | B6: Website Redesign - Cloud | C6: Priya Singh | D6: Low | E6: 45454 | F6: 45496 | G6: 13.6 | H6: 11.8 | I6: Completed | J6: -1.8
A7: TSK3005 | B7: Mobile App - Nova | C7: Isha Bansal | D7: High | E7: 44926 | G7: 48.4 | H7: 35.9 | I7: Open | J7: -12.5
A8: TSK3006 | B8: CRM Integration - Nova | C8: Neha Kapoor | D8: Critical | E8: 44634 | F8: 44654 | G8: 56.6 | H8: 87.3 | I8: Completed | J8: 30.7
A9: TSK3007 | B9: CRM Integration - Nova | C9: Riya Sharma | D9: Low | E9: 44623 | F9: 44651 | G9: 59.3 | H9: 71.4 | I9: Completed | J9: 12.1
A10: TSK3008 | B10: Mobile App - Pixel | C10: Tanvi Desai | D10: High | E10: 44956 | G10: 37.1 | H10: 40.1 | I10: Open | J10: 3
A11: TSK3009 | B11: E-commerce Platform - Nova | C11: Vikram Joshi | D11: High | E11: 45794 | G11: 15.7 | H11: 7.3 | I11: Open | J11: -8.4
A12: TSK3010 | B12: POS System - Grand | C12: Ananya Rao | D12: High | E12: 44761 | F12: 44793 | G12: 77.6 | H12: 83 | I12: Completed | J12: 5.4
A13: TSK3011 | B13: Cloud Migration - Tech | C13: Sneha Patel | D13: Critical | E13: 45667 | F13: 45678 | G13: 27.7 | H13: 35.8 | I13: Completed | J13: 8.1
A14: TSK3012 | B14: E-commerce Platform - Tech | C14: Tanvi Desai | D14: Critical | E14: 45658 | F14: 45679 | G14: 21.7 | H14: 15.5 | I14: Completed | J14: -6.2
A15: TSK3013 | B15: Inventory Management - Apex | C15: Neha Kapoor | D15: High | E15: 45133 | F15: 45168 | G15: 38 | H15: 24.9 | I15: Completed | J15: -13.1
A16: TSK3014 | B16: Booking System - Crest | C16: Neha Kapoor | D16: Medium | E16: 45825 | F16: 45854 | G16: 61.3 | H16: 0 | I16: Completed | J16: -61.3
A17: TSK3015 | B17: Mobile App - Bright | C17: Pooja Reddy | D17: Medium | E17: 45021 | G17: 39.8 | H17: 1 | I17: Open | J17: -38.8
A18: TSK3016 | B18: Inventory Management - Pixel | C18: Manish Kumar | D18: Low | E18: 45272 | F18: 45308 | G18: 33.8 | H18: 27.9 | I18: Completed | J18: -5.9
A19: TSK3017 | B19: Mobile App - Swift | C19: Neha Kapoor | D19: High | E19: 45404 | F19: 45414 | G19: 40.9 | H19: 53.8 | I19: Completed | J19: 12.9
A20: TSK3018 | B20: E-commerce Platform - Vivid | C20: Ananya Rao | D20: Medium | E20: 45461 | G20: 21 | H20: 10.4 | I20: Open | J20: -10.6
A21: TSK3019 | B21: Analytics Dashboard - Bright | C21: Tanvi Desai | D21: Critical | E21: 45069 | F21: 45078 | G21: 69.4 | H21: 60.8 | I21: Completed | J21: -8.6
A22: TSK3020 | B22: CRM Integration - Tech | C22: Arjun Nair | D22: Critical | E22: 45604 | F22: 45605 | G22: 24.1 | H22: 21.7 | I22: Completed | J22: -2.4
A23: TSK3021 | B23: ERP System - Nova | C23: Ananya Rao | D23: Critical | E23: 45793 | F23: 45816 | G23: 27.9 | H23: 38 | I23: Completed | J23: 10.1
A24: TSK3022 | B24: Cloud Migration - Tech | C24: Manish Kumar | D24: Critical | E24: 45544 | G24: 20.6 | H24: 7.1 | I24: Open | J24: -13.5
A25: TSK3023 | B25: Website Redesign - Crest | C25: Manish Kumar | D25: Medium | E25: 45781 | F25: 45806 | G25: 32.1 | H25: 40.6 | I25: Completed | J25: 8.5
A26: TSK3024 | B26: POS System - Nova | C26: Manish Kumar | D26: Critical | E26: 45462 | F26: 45500 | G26: 27.9 | H26: 19.5 | I26: Completed | J26: -8.4
A27: TSK3025 | B27: ERP System - Vivid | C27: Manish Kumar | D27: Medium | E27: 45239 | G27: 3.2 | H27: 0.4 | I27: Open | J27: -2.8
A28: TSK3026 | B28: CRM Integration - Apex | C28: Ananya Rao | D28: Low | E28: 45540 | G28: 22.7 | H28: 12.7 | I28: Open | J28: -10
A29: TSK3027 | B29: HRMS Portal - Urban | C29: Siddharth Iyer | D29: Critical | E29: 45640 | G29: 31.6 | H29: 9 | I29: Open | J29: -22.6
A30: TSK3028 | B30: Analytics Dashboard - Royal | C30: Karan Mehta | D30: Low | E30: 45024 | F30: 45040 | G30: 51.2 | H30: 77.9 | I30: Completed | J30: 26.7
A31: TSK3029 | B31: CRM Integration - Royal | C31: Priya Singh | D31: High | E31: 45046 | G31: 56.9 | H31: 5.1 | I31: Open | J31: -51.8
A32: TSK3030 | B32: Website Redesign - Cloud | C32: Priya Singh | D32: Medium | E32: 45057 | F32: 45061 | G32: 24.9 | H32: 24.3 | I32: Completed | J32: -0.6
A33: TSK3031 | B33: Analytics Dashboard - Bharat | C33: Manish Kumar | D33: Critical | E33: 45232 | F33: 45244 | G33: 15.3 | H33: 10.4 | I33: Completed | J33: -4.9
A34: TSK3032 | B34: Booking System - Crest | C34: Sneha Patel | D34: Critical | E34: 45806 | F34: 45844 | G34: 13.2 | H34: 14 | I34: Completed | J34: 0.8
A35: TSK3033 | B35: Payment Gateway - Tech | C35: Priya Singh | D35: Low | E35: 45347 | F35: 45377 | G35: 72.3 | H35: 92.4 | I35: Completed | J35: 20.1
A36: TSK3034 | B36: CRM Integration - Nova | C36: Siddharth Iyer | D36: High | E36: 44691 | G36: 25.3 | H36: 21.9 | I36: Open | J36: -3.4
A37: TSK3035 | B37: HRMS Portal - Grand | C37: Ananya Rao | D37: High | E37: 44974 | F37: 44999 | G37: 68.6 | H37: 48.5 | I37: Completed | J37: -20.1
A38: TSK3036 | B38: E-commerce Platform - Nova | C38: Pooja Reddy | D38: Critical | E38: 45859 | G38: 25 | H38: 22 | I38: Open | J38: -3
A39: TSK3037 | B39: Analytics Dashboard - Swift | C39: Isha Bansal | D39: Critical | E39: 45806 | F39: 45850 | G39: 62.7 | H39: 98.7 | I39: Completed | J39: 36
A40: TSK3038 | B40: Mobile App - Bright | C40: Pooja Reddy | D40: Medium | E40: 45107 | G40: 49.4 | H40: 15.7 | I40: Open | J40: -33.7
...

Sheet Invoices
A1: invoice_id | B1: client_name | C1: invoice_date | D1: invoice_amount | E1: gst | F1: payment_status | G1: due_date | H1: paid_date | I1: total_amount | J1: is_overdue
A2: INV4000 | B2: Vivid Ventures | C2: 45717 | D2: 208043.77 | E2: 37447.88 | F2: Unpaid | G2: 45732 | I2: 245491.65 | J2: =TRUE() -> TRUE
A3: INV4001 | B3: Grand Systems | C3: 44951 | D3: 748461.03 | E3: 134722.99 | F3: Paid | G3: 44981 | H3: 44964 | I3: 883184.02 | J3: =FALSE() -> FALSE
A4: INV4002 | B4: Silver Systems | C4: 45788 | D4: 446157.85 | E4: 80308.41 | F4: Paid | G4: 45818 | H4: 45813 | I4: 526466.26 | J4: =FALSE() -> FALSE
A5: INV4003 | B5: Grand Technologies | C5: 45076 | D5: 478143.53 | E5: 86065.84 | F5: Paid | G5: 45091 | H5: 45095 | I5: 564209.37 | J5: =FALSE() -> FALSE
A6: INV4004 | B6: Pixel Works | C6: 45050 | D6: 415156.27 | E6: 74728.13 | F6: Paid | G6: 45080 | I6: 489884.4 | J6: =FALSE() -> FALSE
A7: INV4005 | B7: Vivid Works | C7: 45777 | D7: 567412.3 | E7: 102134.21 | F7: Paid | G7: 45807 | H7: 45800 | I7: 669546.51 | J7: =FALSE() -> FALSE
A8: INV4006 | B8: Quantum Industries | C8: 45239 | D8: 85205.72 | E8: 15337.03 | F8: Paid | G8: 45269 | H8: 45250 | I8: 100542.75 | J8: =FALSE() -> FALSE
A9: INV4007 | B9: Quantum Corp | C9: 45245 | D9: 274865.23 | E9: 49475.74 | F9: Unpaid | G9: 45290 | I9: 324340.97 | J9: =TRUE() -> TRUE
A10: INV4008 | B10: Cloud Net | C10: 45062 | D10: 564967.19 | E10: 101694.09 | F10: Overdue | G10: 45092 | I10: 666661.28 | J10: =TRUE() -> TRUE
A11: INV4009 | B11: Quantum Enterprises | C11: 45045 | D11: 250000 | E11: 15704.28 | F11: Paid | G11: 45060 | H11: 45056 | I11: 265704.28 | J11: =FALSE() -> FALSE
A12: INV4010 | B12: Silver Ventures | C12: 45039 | D12: 539542.07 | E12: 97117.57 | F12: Unpaid | G12: 45069 | I12: 636659.64 | J12: =TRUE() -> TRUE
A13: INV4011 | B13: Crest Hub | C13: 45171 | D13: 572162.47 | E13: 102989.24 | F13: Overdue | G13: 45186 | I13: 675151.71 | J13: =TRUE() -> TRUE
A14: INV4012 | B14: Quantum Works | C14: 45943 | D14: 427944.18 | E14: 77029.95 | F14: Overdue | G14: 45973 | I14: 504974.13 | J14: =TRUE() -> TRUE
A15: INV4013 | B15: Grand Works | C15: 45457 | D15: 310058.16 | E15: 55810.47 | F15: Overdue | G15: 45472 | I15: 365868.63 | J15: =TRUE() -> TRUE
A16: INV4014 | B16: Royal Solutions | C16: 45168 | D16: 281308.6 | E16: 50635.55 | F16: Paid | G16: 45183 | H16: 45177 | I16: 331944.15 | J16: =FALSE() -> FALSE
A17: INV4015 | B17: Grand Systems | C17: 45465 | D17: 780539.46 | E17: 140497.1 | F17: Unpaid | G17: 45510 | I17: 921036.56 | J17: =TRUE() -> TRUE
A18: INV4016 | B18: Vivid Ventures | C18: 45859 | D18: 300896.64 | E18: 54161.4 | F18: Paid | G18: 45904 | H18: 45896 | I18: 355058.04 | J18: =FALSE() -> FALSE
A19: INV4017 | B19: Quantum Works | C19: 45680 | D19: 218990.54 | E19: 39418.3 | F19: Paid | G19: 45695 | H19: 45687 | I19: 258408.84 | J19: =FALSE() -> FALSE
A20: INV4018 | B20: Grand Net | C20: 45163 | D20: 597808.37 | E20: 107605.51 | F20: Paid | G20: 45178 | H20: 45161 | I20: 705413.88 | J20: =FALSE() -> FALSE
A21: INV4019 | B21: Apex Systems | C21: 45427 | D21: 387976.38 | E21: 69835.75 | F21: Paid | G21: 45442 | H21: 45448 | I21: 457812.13 | J21: =FALSE() -> FALSE
A22: INV4020 | B22: Crest Hub | C22: 44999 | D22: 646430.08 | E22: 116357.41 | F22: Overdue | G22: 45044 | I22: 762787.49 | J22: =TRUE() -> TRUE
A23: INV4021 | B23: Urban Works | C23: 45785 | D23: 271005.57 | E23: 48781 | F23: Paid | G23: 45800 | H23: 45787 | I23: 319786.57 | J23: =FALSE() -> FALSE
A24: INV4022 | B24: Urban Industries | C24: 45482 | D24: 465798.05 | E24: 83843.65 | F24: Paid | G24: 45497 | H24: 45486 | I24: 549641.7 | J24: =FALSE() -> FALSE
A25: INV4023 | B25: Quantum Labs | C25: 45294 | D25: 647383.66 | E25: 116529.06 | F25: Partially Paid | G25: 45309 | H25: 45302 | I25: 763912.72 | J25: =TRUE() -> TRUE
A26: INV4024 | B26: Grand Systems | C26: 45879 | D26: 623351.43 | E26: 112203.26 | F26: Paid | G26: 45909 | H26: 45917 | I26: 735554.69 | J26: =FALSE() -> FALSE
A27: INV4025 | B27: Tech Works | C27: 45862 | D27: 307757.1 | E27: 55396.28 | F27: Paid | G27: 45473 | H27: 45862 | I27: 363153.38 | J27: =FALSE() -> FALSE
A28: INV4026 | B28: Grand Group | C28: 45423 | D28: 307253.43 | E28: 55305.62 | F28: Partially Paid | G28: 45453 | H28: 45452 | I28: 362559.05 | J28: =TRUE() -> TRUE
A29: INV4027 | B29: Grand Works | C29: 45429 | D29: 24974.75 | E29: 4495.45 | F29: Paid | G29: 45444 | H29: 45447 | I29: 29470.2 | J29: =FALSE() -> FALSE
A30: INV4028 | B30: Quantum Industries | C30: 45636 | D30: 674867.73 | E30: 121476.19 | F30: Partially Paid | G30: 45681 | H30: 45676 | I30: 796343.92 | J30: =TRUE() -> TRUE
A31: INV4029 | B31: Apex Systems | C31: 45697 | D31: 587227.73 | E31: 105700.99 | F31: Paid | G31: 45742 | H31: 45736 | I31: 692928.72 | J31: =FALSE() -> FALSE
A32: INV4030 | B32: Quantum Enterprises | C32: 45786 | D32: 769724.35 | E32: 138550.38 | F32: Partially Paid | G32: 45816 | H32: 45817 | I32: 908274.73 | J32: =TRUE() -> TRUE
A33: INV4031 | B33: Bright Technologies | C33: 45500 | D33: 54242.21 | E33: 9763.6 | F33: Paid | G33: 45515 | H33: 45498 | I33: 64005.81 | J33: =FALSE() -> FALSE
A34: INV4032 | B34: Nova Net | C34: 45772 | D34: 718550.79 | E34: 129339.14 | F34: Paid | G34: 45817 | H34: 45804 | I34: 847889.93 | J34: =FALSE() -> FALSE
A35: INV4033 | B35: Apex Corp | C35: 45122 | D35: 124140.8 | E35: 22345.34 | F35: Overdue | G35: 45167 | I35: 146486.14 | J35: =TRUE() -> TRUE
A36: INV4034 | B36: Grand Systems | C36: 45054 | D36: 536706.26 | E36: 96607.13 | F36: Paid | G36: 45084 | H36: 45085 | I36: 633313.39 | J36: =FALSE() -> FALSE
A37: INV4035 | B37: Vivid Industries | C37: 45572 | D37: 566565.97 | E37: 101981.87 | F37: Overdue | G37: 45602 | I37: 668547.84 | J37: =TRUE() -> TRUE
A38: INV4036 | B38: Urban Industries | C38: 45854 | D38: 202216.76 | E38: 36399.02 | F38: Partially Paid | G38: 45884 | H38: 45885 | I38: 238615.78 | J38: =TRUE() -> TRUE
A39: INV4037 | B39: Grand Technologies | C39: 45150 | D39: 102413.05 | E39: 18434.35 | F39: Paid | G39: 45165 | H39: 45165 | I39: 120847.4 | J39: =FALSE() -> FALSE
A40: INV4038 | B40: Grand Enterprises | C40: 45174 | D40: 299464.21 | E40: 53903.56 | F40: Overdue | G40: 45219 | I40: 353367.77 | J40: =TRUE() -> TRUE
...
